2022-04-04 06:01:01.473 | DEBUG    | __main__:<module>:17 - Start script
2022-04-04 06:01:26.482 | DEBUG    | __main__:start_handler:142 - User №471485149 send I'm working)
2022-04-04 06:01:30.889 | DEBUG    | __main__:start_handler:162 - User №471485149 send No records)
2022-04-04 06:20:47.937 | DEBUG    | __main__:<module>:17 - Start script
2022-04-04 06:22:18.209 | DEBUG    | __main__:<module>:17 - Start script
2022-04-04 06:41:40.996 | DEBUG    | __main__:start_handler:162 - User №471485149 send No records)
2022-04-04 06:45:49.837 | DEBUG    | __main__:check_old_data:113 - (706, 'EOSUSDT', 2.775, 161177.6, '2022-04-04 06:04:34.339291', 0) -0.0061261261261260636)
2022-04-04 06:54:29.275 | DEBUG    | __main__:start_handler:159 - User №{message.chat.id} send {all_verified_message}
2022-04-04 06:55:58.926 | DEBUG    | __main__:start_handler:162 - User №471485149 send No records)
2022-04-04 06:56:14.117 | ERROR    | __main__:polling:133 - HTTPSConnectionPool(host='api.telegram.org', port=443): Max retries exceeded with url: /bot5276441681:AAHi9DX8ZYWVlm49AEBU1be0gVEXWmeKoZ8/sendMessage?chat_id=471485149&text=No+records (Caused by ConnectTimeoutError(<urllib3.connection.HTTPSConnection object at 0x00000183745AC190>, 'Connection to api.telegram.org timed out. (connect timeout=15)'))
2022-04-04 06:56:40.663 | DEBUG    | __main__:start_handler:162 - User №471485149 send No records)
2022-04-04 06:57:32.376 | DEBUG    | __main__:check_old_data:113 - (706, 'EOSUSDT', 2.775, 161299.2, '2022-04-04 06:04:34.339291', 1) -0.005765765765765707)
2022-04-04 06:58:19.978 | DEBUG    | __main__:start_handler:159 - User №{message.chat.id} send {all_verified_message}
2022-04-04 06:58:47.167 | DEBUG    | __main__:start_handler:159 - User №{message.chat.id} send {all_verified_message}
2022-04-04 07:03:40.312 | DEBUG    | __main__:start_handler:162 - User №471485149 send No records)
2022-04-04 07:03:43.157 | DEBUG    | __main__:start_handler:162 - User №471485149 send No records)
2022-04-04 07:03:44.523 | DEBUG    | __main__:start_handler:162 - User №471485149 send No records)
2022-04-04 07:03:45.450 | DEBUG    | __main__:start_handler:162 - User №471485149 send No records)
2022-04-04 07:04:37.726 | DEBUG    | __main__:<module>:17 - Start script
2022-04-04 07:05:22.569 | DEBUG    | __main__:check_old_data:113 - (2, 'ATOMUSDT', 31.52, 15082.79, '2022-04-04 04:18:35.015786', 0) -0.008883248730964466)
2022-04-04 07:10:18.167 | DEBUG    | __main__:check_old_data:113 - (1, 'AVAXUSDT', 95.87, 5389.41, '2022-04-04 06:52:18.057164', 0) -0.0031292375091269697)
2022-04-04 07:10:19.462 | DEBUG    | __main__:check_old_data:113 - (2, 'ATOMUSDT', 31.52, 15098.24, '2022-04-04 04:18:35.015786', 1) -0.006027918781726038)
2022-04-04 07:15:26.987 | DEBUG    | __main__:<module>:17 - Start script
2022-04-04 07:16:14.101 | DEBUG    | __main__:check_old_data:113 - (1, 'AVAXUSDT', 95.87, 5451.78, '2022-04-04 06:52:18.057164', 1) -0.007823093772817424)
2022-04-04 07:16:44.404 | DEBUG    | __main__:start_handler:159 - User №{message.chat.id} send {all_verified_message}
2022-04-04 07:19:52.230 | ERROR    | __main__:check_old_data:118 - HTTPSConnectionPool(host='api1.binance.com', port=443): Read timed out. (read timeout=None)
2022-04-04 07:20:04.636 | ERROR    | __main__:polling:133 - ('Connection aborted.', RemoteDisconnected('Remote end closed connection without response'))
2022-04-04 07:20:14.635 | ERROR    | __main__:check_old_data:118 - HTTPSConnectionPool(host='api1.binance.com', port=443): Max retries exceeded with url: /api/v3/ticker/price?symbol=AVAXUSDT (Caused by NewConnectionError('<urllib3.connection.HTTPSConnection object at 0x00000287E25DC040>: Failed to establish a new connection: [Errno 11001] getaddrinfo failed'))
2022-04-04 07:20:26.146 | ERROR    | __main__:polling:133 - HTTPSConnectionPool(host='api.telegram.org', port=443): Max retries exceeded with url: /bot5276441681:AAHi9DX8ZYWVlm49AEBU1be0gVEXWmeKoZ8/getUpdates?offset=575910160&timeout=20 (Caused by NewConnectionError('<urllib3.connection.HTTPSConnection object at 0x00000287E25DE140>: Failed to establish a new connection: [Errno 11001] getaddrinfo failed'))
2022-04-04 07:20:38.060 | ERROR    | __main__:check_old_data:118 - HTTPSConnectionPool(host='api1.binance.com', port=443): Max retries exceeded with url: /api/v3/ticker/price?symbol=AVAXUSDT (Caused by NewConnectionError('<urllib3.connection.HTTPSConnection object at 0x00000287E25DCE50>: Failed to establish a new connection: [Errno 11001] getaddrinfo failed'))
2022-04-04 07:20:39.642 | ERROR    | __main__:polling:133 - HTTPSConnectionPool(host='api.telegram.org', port=443): Max retries exceeded with url: /bot5276441681:AAHi9DX8ZYWVlm49AEBU1be0gVEXWmeKoZ8/getUpdates?offset=575910160&timeout=20 (Caused by NewConnectionError('<urllib3.connection.HTTPSConnection object at 0x00000287E27F1120>: Failed to establish a new connection: [Errno 11001] getaddrinfo failed'))
2022-04-04 07:20:48.807 | ERROR    | __main__:check_old_data:118 - HTTPSConnectionPool(host='api1.binance.com', port=443): Max retries exceeded with url: /api/v3/ticker/price?symbol=AVAXUSDT (Caused by NewConnectionError('<urllib3.connection.HTTPSConnection object at 0x00000287E28485E0>: Failed to establish a new connection: [Errno 11001] getaddrinfo failed'))
2022-04-04 07:20:50.013 | ERROR    | __main__:polling:133 - HTTPSConnectionPool(host='api.telegram.org', port=443): Max retries exceeded with url: /bot5276441681:AAHi9DX8ZYWVlm49AEBU1be0gVEXWmeKoZ8/getUpdates?offset=575910160&timeout=20 (Caused by NewConnectionError('<urllib3.connection.HTTPSConnection object at 0x00000287E27F2CE0>: Failed to establish a new connection: [Errno 11001] getaddrinfo failed'))
2022-04-04 07:21:05.930 | DEBUG    | __main__:check_old_data:113 - (1, 'AVAXUSDT', 95.87, 5456.46, '2022-04-04 06:52:18.057164', 1) -0.008448941274642685)
2022-04-04 07:21:24.143 | ERROR    | __main__:polling:133 - HTTPSConnectionPool(host='api.telegram.org', port=443): Max retries exceeded with url: /bot5276441681:AAHi9DX8ZYWVlm49AEBU1be0gVEXWmeKoZ8/getUpdates?offset=575910160&timeout=20 (Caused by ConnectTimeoutError(<urllib3.connection.HTTPSConnection object at 0x00000287E2849210>, 'Connection to api.telegram.org timed out. (connect timeout=20)'))
2022-04-04 07:24:19.367 | DEBUG    | __main__:<module>:17 - Start script
2022-04-04 07:24:29.419 | DEBUG    | __main__:<module>:17 - Start script
2022-04-04 07:25:20.173 | DEBUG    | __main__:<module>:17 - Start script
2022-04-04 07:25:28.806 | DEBUG    | __main__:<module>:17 - Start script
2022-04-04 07:26:14.345 | DEBUG    | __main__:check_old_data:113 - (1, 'AVAXUSDT', 95.87, 5275.3, '2022-04-04 06:52:18.057164', 1) -0.009909252112235256)
2022-04-04 07:38:19.830 | DEBUG    | __main__:<module>:17 - Start script
2022-04-04 07:39:04.096 | ERROR    | __main__:check_old_data:119 - strptime() argument 1 must be str, not int
2022-04-04 07:40:46.971 | DEBUG    | __main__:<module>:17 - Start script
2022-04-04 07:43:24.741 | DEBUG    | __main__:<module>:17 - Start script
2022-04-04 07:43:33.859 | ERROR    | db_requests:update_record:182 - Ошибка при работе с SQLite
2022-04-04 07:43:38.890 | ERROR    | db_requests:insert_first:146 - Ошибка при работе с SQLite
2022-04-04 07:43:42.790 | DEBUG    | __main__:<module>:17 - Start script
2022-04-04 07:43:46.479 | ERROR    | __main__:check_old_data:118 - strptime() argument 1 must be str, not int
2022-04-04 07:44:45.179 | DEBUG    | __main__:<module>:17 - Start script
2022-04-04 07:45:18.412 | DEBUG    | __main__:<module>:17 - Start script
2022-04-04 07:45:45.375 | DEBUG    | __main__:<module>:17 - Start script
2022-04-04 07:45:50.878 | DEBUG    | __main__:check_old_data:113 - (1, 'AVAXUSDT', 95.87, 5276.07, '2000-01-01 07:40:56.181990', '2000-01-01 00:00:00.000000', 0) -0.009700636278293429)
2022-04-04 07:45:53.844 | DEBUG    | __main__:check_old_data:113 - (1, 'AVAXUSDT', 95.87, 5276.07, '2000-01-01 07:40:56.181990', '2000-01-01 00:00:00.000000', 1) -0.009700636278293429)
2022-04-04 07:45:56.889 | DEBUG    | __main__:check_old_data:113 - (1, 'AVAXUSDT', 95.87, 5276.07, '2000-01-01 07:40:56.181990', '2000-01-01 00:00:00.000000', 1) -0.009492020444351601)
2022-04-04 07:45:59.818 | DEBUG    | __main__:check_old_data:113 - (1, 'AVAXUSDT', 95.87, 5276.07, '2000-01-01 07:40:56.181990', '2000-01-01 00:00:00.000000', 1) -0.009596328361322737)
2022-04-04 07:49:41.633 | DEBUG    | __main__:<module>:17 - Start script
2022-04-04 07:49:49.445 | DEBUG    | __main__:check_old_data:113 - (1, 'AVAXUSDT', 95.87, 5284.39, '2000-01-01 07:40:56.181990', '2000-04-04 07:48:00.661075', 0) -0.009909252112235256)
2022-04-04 07:50:53.744 | DEBUG    | __main__:start_handler:162 - User №471485149 send No records)
2022-04-04 07:51:29.239 | DEBUG    | __main__:start_handler:162 - User №471485149 send No records)
2022-04-04 07:53:51.129 | DEBUG    | __main__:<module>:17 - Start script
2022-04-04 07:54:15.715 | DEBUG    | __main__:<module>:17 - Start script
2022-04-04 07:56:37.909 | DEBUG    | __main__:<module>:17 - Start script
2022-04-04 07:57:06.372 | DEBUG    | __main__:<module>:17 - Start script
2022-04-04 07:58:23.720 | DEBUG    | __main__:<module>:17 - Start script
2022-04-04 07:58:32.526 | ERROR    | db_requests:insert_first:146 - Ошибка при работе с SQLite
2022-04-04 07:58:37.657 | ERROR    | db_requests:insert_first:146 - Ошибка при работе с SQLite
2022-04-04 07:58:40.081 | DEBUG    | __main__:<module>:17 - Start script
2022-04-04 07:58:44.449 | DEBUG    | __main__:check_old_data:114 - (1, 'AVAXUSDT', 95.87, 5282.93, '2022-04-03 07:57:12.438986', '2000-01-01 00:00:00.000000', 0) -0.006467090852195545)
2022-04-04 07:58:45.869 | ERROR    | db_requests:update_out_from_range:200 - Ошибка при работе с SQLite
2022-04-04 07:58:48.446 | ERROR    | db_requests:update_out_from_range:200 - Ошибка при работе с SQLite
2022-04-04 07:58:50.167 | ERROR    | db_requests:update_out_from_range:200 - Ошибка при работе с SQLite
2022-04-04 07:59:48.103 | DEBUG    | __main__:<module>:17 - Start script
2022-04-04 08:05:01.112 | DEBUG    | __main__:<module>:17 - Start script
2022-04-04 08:05:28.024 | DEBUG    | __main__:start_handler:160 - User №{message.chat.id} send {all_verified_message}
2022-04-04 08:05:35.956 | ERROR    | __main__:check_old_data:119 - tuple index out of range
2022-04-04 08:05:51.169 | ERROR    | __main__:check_old_data:119 - tuple index out of range
2022-04-04 08:09:06.977 | DEBUG    | __main__:<module>:17 - Start script
2022-04-04 08:09:12.682 | ERROR    | __main__:check_old_data:119 - tuple index out of range
2022-04-04 08:09:24.100 | ERROR    | __main__:check_old_data:119 - tuple index out of range
2022-04-04 08:09:34.734 | ERROR    | __main__:check_old_data:119 - tuple index out of range
2022-04-04 08:09:46.205 | ERROR    | __main__:check_old_data:119 - tuple index out of range
2022-04-04 08:09:57.474 | ERROR    | __main__:check_old_data:119 - tuple index out of range
2022-04-04 08:12:46.943 | DEBUG    | __main__:<module>:17 - Start script
2022-04-04 08:12:52.518 | ERROR    | db_requests:select_get_an_accepted_records:63 - Ошибка при работе с SQLite
2022-04-04 08:12:56.400 | ERROR    | db_requests:select_get_an_accepted_records:63 - Ошибка при работе с SQLite
2022-04-04 08:12:57.706 | ERROR    | db_requests:select_get_an_accepted_records:63 - Ошибка при работе с SQLite
2022-04-04 08:12:58.835 | ERROR    | db_requests:select_get_an_accepted_records:63 - Ошибка при работе с SQLite
2022-04-04 08:12:59.790 | ERROR    | db_requests:select_get_an_accepted_records:63 - Ошибка при работе с SQLite
2022-04-04 08:13:00.758 | ERROR    | db_requests:select_get_an_accepted_records:63 - Ошибка при работе с SQLite
2022-04-04 08:13:04.679 | ERROR    | db_requests:select_get_an_accepted_records:63 - Ошибка при работе с SQLite
2022-04-04 08:13:06.524 | ERROR    | db_requests:select_get_an_accepted_records:63 - Ошибка при работе с SQLite
2022-04-04 08:13:32.668 | DEBUG    | __main__:<module>:17 - Start script
2022-04-04 08:13:39.351 | ERROR    | db_requests:select_get_an_accepted_records:63 - Ошибка при работе с SQLite
2022-04-04 08:13:42.867 | ERROR    | db_requests:select_get_an_accepted_records:63 - Ошибка при работе с SQLite
2022-04-04 08:13:43.850 | ERROR    | db_requests:select_get_an_accepted_records:63 - Ошибка при работе с SQLite
2022-04-04 08:13:48.123 | ERROR    | db_requests:select_get_an_accepted_records:63 - Ошибка при работе с SQLite
2022-04-04 08:13:57.883 | ERROR    | db_requests:select_get_an_accepted_records:63 - Ошибка при работе с SQLite
2022-04-04 08:14:25.849 | DEBUG    | __main__:<module>:17 - Start script
2022-04-04 08:16:48.983 | DEBUG    | __main__:<module>:17 - Start script
2022-04-04 08:19:32.488 | DEBUG    | __main__:<module>:17 - Start script
2022-04-04 08:19:38.386 | DEBUG    | __main__:check_old_data:114 - (3, 'ATOMUSDT', 32.2, 11247.1, '2022-04-04 07:57:14.861415', '2000-01-01 00:00:00.000000', 0) 0.007763975155279601)
2022-04-04 08:23:12.446 | ERROR    | __main__:check_old_data:119 - HTTPSConnectionPool(host='api1.binance.com', port=443): Max retries exceeded with url: /api/v3/ticker/price?symbol=HNTUSDT (Caused by ConnectTimeoutError(<urllib3.connection.HTTPSConnection object at 0x0000024975002E90>, 'Connection to api1.binance.com timed out. (connect timeout=None)'))
2022-04-04 08:23:12.453 | ERROR    | __main__:polling:134 - ('Connection aborted.', RemoteDisconnected('Remote end closed connection without response'))
2022-04-04 08:24:17.603 | DEBUG    | __main__:<module>:17 - Start script
2022-04-04 08:24:21.220 | DEBUG    | __main__:<module>:17 - Start script
2022-04-04 08:24:42.343 | DEBUG    | __main__:<module>:17 - Start script
2022-04-04 08:25:16.704 | DEBUG    | __main__:<module>:17 - Start script
2022-04-04 08:25:24.981 | DEBUG    | __main__:check_old_data:114 - (1, 'AVAXUSDT', 95.87, 5274.78, '2022-04-03 08:19:36.583342', '2022-04-03 07:58:43.965070', 0) -0.011056639198915308)
2022-04-04 08:26:17.121 | DEBUG    | __main__:check_old_data:114 - (48, 'NEARUSDT', 17.0, 65049.8, '2022-04-04 07:57:50.108932', '2000-01-01 00:00:00.000000', 0) 0.012058823529411677)
2022-04-04 08:27:13.361 | DEBUG    | __main__:<module>:17 - Start script
2022-04-04 08:35:11.742 | DEBUG    | __main__:check_old_data:114 - (3, 'ATOMUSDT', 32.2, 10907.04, '2022-04-04 07:57:14.861415', '2022-04-04 08:19:37.765701', 0) 0.0034161490683229934)
2022-04-04 08:44:33.708 | DEBUG    | __main__:check_old_data:114 - (29, 'ADAUSDT', 1.2, 623287.0, '2022-04-04 07:57:37.901985', '2000-01-01 00:00:00.000000', 0) 0.0024999999999999467)
2022-04-04 09:00:02.771 | DEBUG    | __main__:<module>:17 - Start script
2022-04-04 09:09:27.158 | ERROR    | db_requests:update_record:181 - Ошибка при работе с SQLite
2022-04-04 09:20:34.604 | DEBUG    | __main__:check_old_data:114 - (437, 'AVAXUSDT', 96.5, 4766.2, '2022-04-04 08:32:48.659442', '2000-01-01 00:00:00.000000', 0) -0.003005181347150332)
2022-04-04 09:54:26.080 | DEBUG    | __main__:<module>:17 - Start script
2022-04-04 10:17:53.590 | DEBUG    | __main__:check_old_data:114 - (1109, 'AVAXUSDT', 96.7, 4597.39, '2022-04-04 09:40:18.571169', '2000-01-01 00:00:00.000000', 0) -0.0009307135470528749)
2022-04-04 10:24:18.079 | ERROR    | db_requests:update_record:181 - Ошибка при работе с SQLite
2022-04-04 10:29:45.924 | ERROR    | db_requests:update_record:181 - Ошибка при работе с SQLite
2022-04-04 10:33:13.290 | DEBUG    | __main__:check_old_data:114 - (1228, 'AXSUSDT', 65.81, 7653.95, '2022-04-04 09:51:12.697339', '2000-01-01 00:00:00.000000', 0) -0.0012156207263334107)
2022-04-04 10:40:35.263 | DEBUG    | __main__:start_handler:160 - User №471485149 send Coin: AVAXUSDT
Price: 96.7
Quantity: 4596.52
Amount: 444483.48$
Percentage to density: -0.59%
Date of discovery: 2022-04-04 10:34:10.981278

Coin: AXSUSDT
Price: 65.81
Quantity: 6259.93
Amount: 411965.99$
Percentage to density: -0.38%
Date of discovery: 2022-04-04 09:51:12.697339


2022-04-04 10:42:36.086 | DEBUG    | __main__:start_handler:160 - User №471485149 send Coin: AVAXUSDT
Price: 96.7
Quantity: 4595.96
Amount: 444429.33$
Percentage to density: -0.49%
Date of discovery: 2022-04-04 10:34:10.981278

Coin: AXSUSDT
Price: 65.81
Quantity: 6234.99
Amount: 410324.69$
Percentage to density: -0.27%
Date of discovery: 2022-04-04 09:51:12.697339


2022-04-04 10:43:06.240 | DEBUG    | __main__:check_old_data:114 - (561, 'GALAUSDT', 0.266, 1389888.0, '2022-04-04 08:43:24.666426', '2000-01-01 00:00:00.000000', 0) 0.0036842105263159564)
2022-04-04 10:46:08.393 | DEBUG    | __main__:start_handler:160 - User №471485149 send Coin: GALAUSDT
Price: 0.266
Quantity: 1389697.0
Amount: 369659.4$
Percentage to density: 0.49%
Date of discovery: 2022-04-04 08:43:24.666426

Coin: AVAXUSDT
Price: 96.7
Quantity: 4610.48
Amount: 445833.42$
Percentage to density: -0.8%
Date of discovery: 2022-04-04 10:34:10.981278

Coin: AXSUSDT
Price: 65.81
Quantity: 6113.86
Amount: 402353.13$
Percentage to density: -0.38%
Date of discovery: 2022-04-04 09:51:12.697339


2022-04-04 11:00:45.396 | DEBUG    | __main__:<module>:17 - Start script
2022-04-04 11:04:02.348 | DEBUG    | __main__:start_handler:160 - User №471485149 send all_verified_message
2022-04-04 11:04:17.376 | ERROR    | __main__:polling:134 - HTTPSConnectionPool(host='api.telegram.org', port=443): Max retries exceeded with url: /bot5276441681:AAHi9DX8ZYWVlm49AEBU1be0gVEXWmeKoZ8/sendMessage?chat_id=471485149&text=Coin%3A+AXSUSDT%0APrice%3A+65.81%0AQuantity%3A+6136.92%0AAmount%3A+403870.71%24%0APercentage+to+density%3A+-0.49%25%0ADate+of+discovery%3A+2022-04-04+09%3A51%3A12.697339%0A%0A (Caused by ConnectTimeoutError(<urllib3.connection.HTTPSConnection object at 0x000001F1C20D7880>, 'Connection to api.telegram.org timed out. (connect timeout=15)'))
2022-04-04 11:04:29.347 | DEBUG    | __main__:start_handler:160 - User №471485149 send all_verified_message
2022-04-04 11:06:56.349 | DEBUG    | __main__:start_handler:160 - User №471485149 send all_verified_message
2022-04-04 11:08:30.253 | DEBUG    | __main__:start_handler:160 - User №471485149 send all_verified_message
2022-04-04 11:09:12.994 | DEBUG    | __main__:check_old_data:114 - (725, 'ROSEUSDT', 0.30656, 1790899.6, '2022-04-04 09:17:09.762962', '2000-01-01 00:00:00.000000', 0) -9.78601252608069e-05)
2022-04-04 11:11:06.223 | DEBUG    | __main__:start_handler:160 - User №471485149 send all_verified_message
2022-04-04 11:11:21.606 | DEBUG    | __main__:check_old_data:114 - (1109, 'AVAXUSDT', 96.7, 4613.82, '2022-04-04 10:34:10.981278', '2022-04-04 10:17:52.976639', 0) -0.0023784901758014954)
2022-04-04 11:19:23.699 | DEBUG    | __main__:start_handler:160 - User №471485149 send all_verified_message
2022-04-04 11:26:14.248 | DEBUG    | __main__:<module>:17 - Start script
2022-04-04 11:28:18.941 | DEBUG    | __main__:<module>:17 - Start script
2022-04-04 11:30:53.550 | DEBUG    | __main__:<module>:17 - Start script
